<?xml version="1.0" ?>
<robot name="humanoid_objects">
	<link name="torso_object">
		<inertial>
			<origin rpy="0.00000 -0.00000 0.00000" xyz="-0.01000 0.00000 -0.12000"/>
			<mass value="8.90746"/>
			<inertia ixx="0.21526" ixy="0.00001" ixz="0.00001" iyy="0.21526" iyz="0.00001" izz="0.21526"/>
		</inertial>
		<collision>
			<origin rpy="-1.57080 0.00000 0.00000" xyz="0.00000 0.00000 0.00000"/>
			<geometry>
				<box size="0.14000 0.14000 0.14000"/>
			</geometry>
		</collision>
	</link>
	
	<link name="waist_object">
		<inertial>
			<origin rpy="0.00000 -0.00000 0.00000" xyz="0.00000 0.00000 0.00000"/>
			<mass value="2.26195"/>
			<inertia ixx="0.01357" ixy="0.00001" ixz="0.00001" iyy="0.01357" iyz="0.00001" izz="0.01357"/>
		</inertial>
		<collision>
			<origin rpy="-1.57080 0.00000 0.00000" xyz="0.00000 0.00000 0.00000"/>
			<geometry>
				<box size="0.12000 0.12000 0.12000"/>
			</geometry>
		</collision>
	</link>
	
	<link name="pelvis_object">
		<inertial>
			<origin rpy="0.00000 -0.00000 0.00000" xyz="-0.02000 0.00000 0.00000"/>
			<mass value="6.61619"/>
			<inertia ixx="0.07432" ixy="0.00001" ixz="0.00001" iyy="0.07432" iyz="0.00001" izz="0.07432"/>
		</inertial>
		<collision>
			<origin rpy="-1.57080 0.00000 0.00000" xyz="-0.02000 0.00000 0.00000"/>
			<geometry>
				<box size="0.18000 0.18000 0.14000"/>
			</geometry>
		</collision>
	</link>
	
	<link name="right_thigh_object">
		<inertial>
			<origin rpy="0.00000 -0.00000 0.00000" xyz="0.00000 0.00500 -0.17000"/>
			<mass value="4.75175"/>
			<inertia ixx="0.09212" ixy="0.00001" ixz="0.00001" iyy="0.09212" iyz="0.00001" izz="0.09212"/>
		</inertial>
		<collision>
			<origin rpy="-3.11219 -0.00000 0.00000" xyz="0.00000 0.00500 -0.17000"/>
			<geometry>
				<box size="0.12000 0.12000 0.34015"/>
			</geometry>
		</collision>
	</link>
	
	<link name="right_shin_object">
		<inertial>
			<origin rpy="0.00000 -0.00000 0.00000" xyz="0.00000 0.00000 -0.15000"/>
			<mass value="2.75570"/>
			<inertia ixx="0.03858" ixy="0.00001" ixz="0.00001" iyy="0.03858" iyz="0.00001" izz="0.03858"/>
		</inertial>
		<collision>
			<origin rpy="3.14159 -0.00000 3.14159" xyz="0.00000 0.00000 -0.15000"/>
			<geometry>
				<box size="0.09800 0.09800 0.30000"/>
			</geometry>
		</collision>
	</link>
	
	<link name="right_foot_object">
		<inertial>
			<origin rpy="0.00000 -0.00000 0.00000" xyz="0.03500 0.01000 0.00000"/>
			<mass value="1.13114"/>
			<inertia ixx="0.00828" ixy="0.00001" ixz="0.00001" iyy="0.00828" iyz="0.00001" izz="0.00828"/>
		</inertial>
		<collision>
			<origin rpy="1.57080 1.47585 1.47585" xyz="0.03500 -0.03000 0.00000"/>
			<geometry>
				<box size="0.05400 0.05400 0.21095"/>
			</geometry>
		</collision>
	</link>
	
	<link name="left_thigh_object">
		<inertial>
			<origin rpy="0.00000 -0.00000 0.00000" xyz="0.00000 -0.00500 -0.17000"/>
			<mass value="4.75175"/>
			<inertia ixx="0.09212" ixy="0.00001" ixz="0.00001" iyy="0.09212" iyz="0.00001" izz="0.09212"/>
		</inertial>
		<collision>
			<origin rpy="3.11219 -0.00000 0.00000" xyz="0.00000 -0.00500 -0.17000"/>
			<geometry>
				<box size="0.12000 0.12000 0.34015"/>
			</geometry>
		</collision>
	</link>
	
	<link name="left_shin_object">
		<inertial>
			<origin rpy="0.00000 -0.00000 0.00000" xyz="0.00000 0.00000 -0.15000"/>
			<mass value="2.75570"/>
			<inertia ixx="0.03858" ixy="0.00001" ixz="0.00001" iyy="0.03858" iyz="0.00001" izz="0.03858"/>
		</inertial>
		<collision>
			<origin rpy="3.14159 -0.00000 3.14159" xyz="0.00000 0.00000 -0.15000"/>
			<geometry>
				<box size="0.09800 0.09800 0.30000"/>
			</geometry>
		</collision>
	</link>
	
	<link name="left_foot_object">
		<inertial>
			<origin rpy="0.00000 -0.00000 0.00000" xyz="0.03500 -0.01000 0.00000"/>
			<mass value="1.13114"/>
			<inertia ixx="0.00828" ixy="0.00001" ixz="0.00001" iyy="0.00828" iyz="0.00001" izz="0.00828"/>
		</inertial>
		<collision>
			<origin rpy="-1.57080 1.47585 -1.47585" xyz="0.03500 0.03000 0.00000"/>
			<geometry>
				<box size="0.05400 0.05400 0.21095"/>
			</geometry>
		</collision>
	</link>
	
	<link name="right_upper_arm_object">
		<inertial>
			<origin rpy="0.00000 -0.00000 0.00000" xyz="0.08000 -0.08000 -0.08000"/>
			<mass value="1.66108"/>
			<inertia ixx="0.02368" ixy="0.00001" ixz="0.00001" iyy="0.02368" iyz="0.00001" izz="0.02368"/>
		</inertial>
		<collision>
			<origin rpy="2.35619 0.61548 1.30900" xyz="0.08000 -0.08000 -0.08000"/>
			<geometry>
				<box size="0.08000 0.08000 0.27713"/>
			</geometry>
		</collision>
	</link>
	
	<link name="right_lower_arm_object">
		<inertial>
			<origin rpy="0.00000 -0.00000 0.00000" xyz="0.00000 0.00000 0.00000"/>
			<mass value="1.22954"/>
			<inertia ixx="0.01419" ixy="0.00001" ixz="0.00001" iyy="0.01419" iyz="0.00001" izz="0.01419"/>
		</inertial>
		<collision>
			<origin rpy="-0.78540 0.61548 -0.26180" xyz="0.09000 0.09000 0.09000"/>
			<geometry>
				<box size="0.06200 0.06200 0.27713"/>
			</geometry>
		</collision>
	</link>
	
	<link name="left_upper_arm_object">
		<inertial>
			<origin rpy="0.00000 -0.00000 0.00000" xyz="0.08000 0.08000 -0.08000"/>
			<mass value="1.66108"/>
			<inertia ixx="0.02368" ixy="0.00001" ixz="0.00001" iyy="0.02368" iyz="0.00001" izz="0.02368"/>
		</inertial>
		<collision>
			<origin rpy="-2.35619 0.61548 -1.30900" xyz="0.08000 0.08000 -0.08000"/>
			<geometry>
				<box size="0.08000 0.08000 0.27713"/>
			</geometry>
		</collision>
	</link>
	
	<link name="left_lower_arm_object">
		<inertial>
			<origin rpy="0.00000 -0.00000 0.00000" xyz="0.00000 0.00000 0.00000"/>
			<mass value="1.22954"/>
			<inertia ixx="0.01419" ixy="0.00001" ixz="0.00001" iyy="0.01419" iyz="0.00001" izz="0.01419"/>
		</inertial>
		<collision>
			<origin rpy="0.78540 0.61548 0.26180" xyz="0.09000 -0.09000 0.09000"/>
			<geometry>
				<box size="0.06200 0.06200 0.27713"/>
			</geometry>
		</collision>
	</link>

	<link name="head_object">
		<inertial>
			<origin rpy="0.00000 0.00000 0.00000" xyz="0.00000 0.00000 0.00000"/>
			<mass value="2.0"/>
			<inertia ixx="0.01" ixy="0.0" ixz="0.0" iyy="0.01" iyz="0.0" izz="0.01"/>
		</inertial>
		<collision>
			<origin rpy="0.00000 0.00000 0.00000" xyz="0.00000 0.00000 0.00000"/>
			<geometry>
				<sphere radius="0.10"/>
			</geometry>
		</collision>
	</link>

	<joint name="abdomen_z" type="revolute">
		<parent link="torso_object"/>
		<child link="waist_object"/>
		<dynamics damping="1.0" friction="0.0001"/>
		<origin rpy="0.00000 -0.00400 0.00000" xyz="-0.01026 0.00000 -0.19500"/>
		<axis xyz="0.00000 0.00000 1.00000"/>
		<limit lower="-0.5" upper="0.5" effort="100.0" velocity="10.0"/>
	</joint>
	<joint name="waist_to_pelvis_y" type="revolute">
		<parent link="waist_object"/>
		<child link="pelvis_object"/>
		<dynamics damping="1.0" friction="0.0001"/>
		<origin rpy="0.00000 -0.00000 0.00000" xyz="0.00000 0.00000 -0.10000"/>
		<axis xyz="0.00000 1.00000 0.00000"/>
		<limit lower="-0.3" upper="0.7" effort="100.0" velocity="10.0"/>
	</joint>

	<joint name="right_hip_x" type="revolute">
		<parent link="pelvis_object"/>
		<child link="right_thigh_object"/>
		<dynamics damping="1.0" friction="0.0001"/>
		<origin rpy="0.00000 -0.00000 0.00000" xyz="0.00000 -0.10000 -0.04000"/>
		<axis xyz="1.00000 0.00000 0.00000"/>
		<limit lower="-1.0" upper="0.5" effort="100.0" velocity="10.0"/>
	</joint>
	<joint name="right_knee" type="revolute">
		<parent link="right_thigh_object"/>
		<child link="right_shin_object"/>
		<dynamics damping="1.0" friction="0.0001"/>
		<origin rpy="0.00000 -0.00000 0.00000" xyz="0.00000 0.01000 -0.38300"/>
		<axis xyz="0.00000 1.00000 0.00000"/>
		<limit lower="0.0" upper="2.5" effort="100.0" velocity="10.0"/>
	</joint>
	<joint name="right_ankle_y" type="revolute">
		<parent link="right_shin_object"/>
		<child link="right_foot_object"/>
		<dynamics damping="1.0" friction="0.0001"/>
		<origin rpy="0.00000 -0.00000 0.00000" xyz="0.00000 0.00000 -0.31000"/>
		<axis xyz="0.00000 1.00000 0.00000"/>
		<limit lower="-0.7" upper="0.7" effort="100.0" velocity="10.0"/>
	</joint>

	<joint name="left_hip_x" type="revolute">
		<parent link="pelvis_object"/>
		<child link="left_thigh_object"/>
		<dynamics damping="1.0" friction="0.0001"/>
		<origin rpy="0.00000 -0.00000 0.00000" xyz="0.00000 0.10000 -0.04000"/>
		<axis xyz="-1.00000 0.00000 0.00000"/>
		<limit lower="-0.5" upper="1.0" effort="100.0" velocity="10.0"/>
	</joint>
	<joint name="left_knee" type="revolute">
		<parent link="left_thigh_object"/>
		<child link="left_shin_object"/>
		<dynamics damping="1.0" friction="0.0001"/>
		<origin rpy="0.00000 -0.00000 0.00000" xyz="0.00000 -0.01000 -0.38300"/>
		<axis xyz="0.00000 1.00000 0.00000"/>
		<limit lower="0.0" upper="2.5" effort="100.0" velocity="10.0"/>
	</joint>
	<joint name="left_ankle_y" type="revolute">
		<parent link="left_shin_object"/>
		<child link="left_foot_object"/>
		<dynamics damping="1.0" friction="0.0001"/>
		<origin rpy="0.00000 -0.00000 0.00000" xyz="0.00000 0.00000 -0.31000"/>
		<axis xyz="0.00000 1.00000 0.00000"/>
		<limit lower="-0.7" upper="0.7" effort="100.0" velocity="10.0"/>
	</joint>

	<joint name="right_shoulder1" type="revolute">
		<parent link="torso_object"/>
		<child link="right_upper_arm_object"/>
		<dynamics damping="1.0" friction="0.0001"/>
		<origin rpy="0.00000 -0.00000 0.00000" xyz="0.00000 -0.17000 0.06000"/>
		<axis xyz="0.00000 1.00000 0.00000"/>
		<limit lower="-2.0" upper="2.0" effort="100.0" velocity="10.0"/>
	</joint>
	<joint name="right_elbow" type="revolute">
		<parent link="right_upper_arm_object"/>
		<child link="right_lower_arm_object"/>
		<dynamics damping="1.0" friction="0.0001"/>
		<origin rpy="0.00000 -0.00000 0.00000" xyz="0.18000 -0.18000 -0.18000"/>
		<axis xyz="0.00000 1.00000 0.00000"/>
		<limit lower="0.0" upper="2.5" effort="100.0" velocity="10.0"/>
	</joint>

	<joint name="left_shoulder1" type="revolute">
		<parent link="torso_object"/>
		<child link="left_upper_arm_object"/>
		<dynamics damping="1.0" friction="0.0001"/>
		<origin rpy="0.00000 -0.00000 0.00000" xyz="0.00000 0.17000 0.06000"/>
		<axis xyz="0.00000 1.00000 0.00000"/>
		<limit lower="-2.0" upper="2.0" effort="100.0" velocity="10.0"/>
	</joint>
	<joint name="left_elbow" type="revolute">
		<parent link="left_upper_arm_object"/>
		<child link="left_lower_arm_object"/>
		<dynamics damping="1.0" friction="0.0001"/>
		<origin rpy="0.00000 -0.00000 0.00000" xyz="0.18000 0.18000 -0.18000"/>
		<axis xyz="0.00000 1.00000 0.00000"/>
		<limit lower="0.0" upper="2.5" effort="100.0" velocity="10.0"/>
	</joint>

	<joint name="neck_joint" type="revolute">
		<parent link="torso_object"/>
		<child link="head_object"/>
		<dynamics damping="1.0" friction="0.0001"/>
		<origin rpy="0.00000 0.00000 0.00000" xyz="0.00000 0.00000 0.20000"/>
		<axis xyz="0.00000 1.00000 0.00000"/>
		<limit lower="-0.5" upper="0.5" effort="100.0" velocity="10.0"/>
	</joint>
</robot>